Workbook

Sheet Dashboard
A1: Barrister Source of Truth — Authoritative Master | Verified Through Event 84
A3: Events 1–84 verified as the locked chronology; 79 payment records confirmed and 5 payment breakdowns remain pending.
A5: Completed Events | C5: Unique Clients | E5: Unique Work Orders | G5: Confirmed Revenue | I5: Pending Breakdown | K5: Pending ACH | M5: Open Exceptions
A6: 84 | C6: 31 | E6: 85 | G6: 9474.41 | I6: 5 | K6: 15 | M6: 5
A9: Financial Performance
A10: Avg / Eligible Event | C10: Avg / Workweek | E10: Worked Days | G10: Avg / Worked Day | I10: Breakdown Completion | K10: ACH Completion | M10: Outstanding Confirmed
A11: 119.92924 | C11: 676.74357 | E11: 54 | G11: 175.45204 | I11: 0.94047619 | K11: 0.8358209 | M11: 2150.39
A14: Operational Performance
A15: Current Workweek | C15: Current MY_MONTH | E15: Workday Utilization | G15: Events / Week | I15: Revenue / Week | K15: Mapping Holds | M15: Variance Exposure
A16: 14 | C16: MY_MONTH 4 — ACTIVE | E16: 0.77142857 | G16: 6 | I16: 676.74357 | K16: 0 | M16: 0
A18: Financial-Scope Events: 84 | Breakdown Confirmed: 79 | Breakdown Pending: 5 | Self-Healing: ACTIVE
A19: Weekday Performance | I19: Top Clients by Confirmed Revenue
A20: Weekday | B20: Confirmed Revenue | C20: Eligible Events | D20: Avg / Event | E20: Active Weeks | F20: Activity Rate | G20: Revenue Rank | I20: Rank | J20: Client | K20: Revenue | L20: Events | M20: Avg / Event | N20: Repeat
A21: =Analytics!J43 | B21: =Analytics!K43 | C21: =Analytics!L43 | D21: =Analytics!M43 | E21: =Analytics!N43 | F21: =Analytics!O43 | G21: =Analytics!R43 | I21: 1 | J21: =INDEX(tblClientSummary[Client Name],MATCH(LARGE(tblClientSummary[Confirmed Revenue],I21),tblClientSummary[Confirmed Revenue],0)) | K21: =LARGE(tblClientSummary[Confirmed Revenue],I21) | L21: =INDEX(tblClientSummary[Total Events],MATCH(K21,tblClientSummary[Confirmed Revenue],0)) | M21: =INDEX(tblClientSummary[Avg Revenue / Event],MATCH(K21,tblClientSummary[Confirmed Revenue],0)) | N21: =INDEX(tblClientSummary[Repeat Client],MATCH(K21,tblClientSummary[Confirmed Revenue],0))
A22: =Analytics!J44 | B22: =Analytics!K44 | C22: =Analytics!L44 | D22: =Analytics!M44 | E22: =Analytics!N44 | F22: =Analytics!O44 | G22: =Analytics!R44 | I22: 2 | J22: =INDEX(tblClientSummary[Client Name],MATCH(LARGE(tblClientSummary[Confirmed Revenue],I22),tblClientSummary[Confirmed Revenue],0)) | K22: =LARGE(tblClientSummary[Confirmed Revenue],I22) | L22: =INDEX(tblClientSummary[Total Events],MATCH(K22,tblClientSummary[Confirmed Revenue],0)) | M22: =INDEX(tblClientSummary[Avg Revenue / Event],MATCH(K22,tblClientSummary[Confirmed Revenue],0)) | N22: =INDEX(tblClientSummary[Repeat Client],MATCH(K22,tblClientSummary[Confirmed Revenue],0))
A23: =Analytics!J45 | B23: =Analytics!K45 | C23: =Analytics!L45 | D23: =Analytics!M45 | E23: =Analytics!N45 | F23: =Analytics!O45 | G23: =Analytics!R45 | I23: 3 | J23: =INDEX(tblClientSummary[Client Name],MATCH(LARGE(tblClientSummary[Confirmed Revenue],I23),tblClientSummary[Confirmed Revenue],0)) | K23: =LARGE(tblClientSummary[Confirmed Revenue],I23) | L23: =INDEX(tblClientSummary[Total Events],MATCH(K23,tblClientSummary[Confirmed Revenue],0)) | M23: =INDEX(tblClientSummary[Avg Revenue / Event],MATCH(K23,tblClientSummary[Confirmed Revenue],0)) | N23: =INDEX(tblClientSummary[Repeat Client],MATCH(K23,tblClientSummary[Confirmed Revenue],0))
A24: =Analytics!J46 | B24: =Analytics!K46 | C24: =Analytics!L46 | D24: =Analytics!M46 | E24: =Analytics!N46 | F24: =Analytics!O46 | G24: =Analytics!R46 | I24: 4 | J24: =INDEX(tblClientSummary[Client Name],MATCH(LARGE(tblClientSummary[Confirmed Revenue],I24),tblClientSummary[Confirmed Revenue],0)) | K24: =LARGE(tblClientSummary[Confirmed Revenue],I24) | L24: =INDEX(tblClientSummary[Total Events],MATCH(K24,tblClientSummary[Confirmed Revenue],0)) | M24: =INDEX(tblClientSummary[Avg Revenue / Event],MATCH(K24,tblClientSummary[Confirmed Revenue],0)) | N24: =INDEX(tblClientSummary[Repeat Client],MATCH(K24,tblClientSummary[Confirmed Revenue],0))
A25: =Analytics!J47 | B25: =Analytics!K47 | C25: =Analytics!L47 | D25: =Analytics!M47 | E25: =Analytics!N47 | F25: =Analytics!O47 | G25: =Analytics!R47 | I25: 5 | J25: =INDEX(tblClientSummary[Client Name],MATCH(LARGE(tblClientSummary[Confirmed Revenue],I25),tblClientSummary[Confirmed Revenue],0)) | K25: =LARGE(tblClientSummary[Confirmed Revenue],I25) | L25: =INDEX(tblClientSummary[Total Events],MATCH(K25,tblClientSummary[Confirmed Revenue],0)) | M25: =INDEX(tblClientSummary[Avg Revenue / Event],MATCH(K25,tblClientSummary[Confirmed Revenue],0)) | N25: =INDEX(tblClientSummary[Repeat Client],MATCH(K25,tblClientSummary[Confirmed Revenue],0))
A28: Jurisdiction Snapshot | H28: MY_MONTH Snapshot
A29: Jurisdiction | B29: Events | C29: Clients | D29: Revenue | E29: Avg / Event | F29: Revenue Share | H29: MY_MONTH | I29: Events | J29: Eligible | K29: Clients | L29: Jurisdictions | M29: Revenue | N29: Avg / Event
A30: =Analytics!A43 | B30: =Analytics!B43 | C30: =Analytics!D43 | D30: =Analytics!E43 | E30: =Analytics!F43 | F30: =Analytics!G43 | H30: =Analytics!A52 | I30: =Analytics!B52 | J30: =Analytics!C52 | K30: =Analytics!D52 | L30: =Analytics!E52 | M30: =Analytics!F52 | N30: =Analytics!G52
A31: =Analytics!A44 | B31: =Analytics!B44 | C31: =Analytics!D44 | D31: =Analytics!E44 | E31: =Analytics!F44 | F31: =Analytics!G44 | H31: =Analytics!A53 | I31: =Analytics!B53 | J31: =Analytics!C53 | K31: =Analytics!D53 | L31: =Analytics!E53 | M31: =Analytics!F53 | N31: =Analytics!G53
A32: =Analytics!A45 | B32: =Analytics!B45 | C32: =Analytics!D45 | D32: =Analytics!E45 | E32: =Analytics!F45 | F32: =Analytics!G45 | H32: =Analytics!A54 | I32: =Analytics!B54 | J32: =Analytics!C54 | K32: =Analytics!D54 | L32: =Analytics!E54 | M32: =Analytics!F54 | N32: =Analytics!G54
A33: =Analytics!A46 | B33: =Analytics!B46 | C33: =Analytics!D46 | D33: =Analytics!E46 | E33: =Analytics!F46 | F33: =Analytics!G46
A34: =Analytics!A47 | B34: =Analytics!B47 | C34: =Analytics!D47 | D34: =Analytics!E47 | E34: =Analytics!F47 | F34: =Analytics!G47
A37: Most Recent Completed Events
A38: Event # | B38: Date | C38: Weekday | D38: Client | E38: City | F38: Jurisdiction | G38: Status | H38: Work Orders | I38: Revenue | J38: Eligibility | K38: Visit Type | L38: Mapping / Financial Note | M38: Source | N38: Record ID
A39: 84 | B39: 46227 | C39: Friday | D39: Giant Food Stores | E39: Wheaton | F39: MD | G39: Completed | H39: 5922604 | J39: Pending | K39: Physical Service Visit | L39: Cradlepoint and PoE injector replaced; site restored. Payment breakdown pending. | M39: User completion + Gmail WO assignment and closeout correspondence | N39: EVT-0084
A40: 83 | B40: 46227 | C40: Friday | D40: Carvana | E40: Baltimore | F40: MD | G40: Completed | H40: 5919318 | I40: 65 | J40: Eligible | K40: Physical Service Visit | L40: HP fuser replacement completed; payment breakdown confirmed at $65.00. | M40: User completion + Gmail WO assignment and payment breakdown | N40: EVT-0083
A41: 82 | B41: 46226 | C41: Thursday | D41: TJ Maxx | E41: Alexandria | F41: VA | G41: Completed | H41: 5922683 | I41: 110 | J41: Eligible | K41: Physical Service Visit | L41: BERG adapter service completed; payment breakdown confirmed at $110.00. | M41: User chronology + Gmail ETA and payment breakdown | N41: EVT-0082
A42: 81 | B42: 46226 | C42: Thursday | D42: HomeGoods | E42: Fairfax | F42: VA | G42: Completed | H42: 5922660 | I42: 125 | J42: Eligible | K42: Physical Service Visit | L42: Power USB cable service completed; payment breakdown confirmed at $125.00. | M42: User chronology + Gmail ETA and payment breakdown | N42: EVT-0081
A43: 80 | B43: 46226 | C43: Thursday | D43: Marshalls | E43: Westminster | F43: MD | G43: Completed | H43: 5906863 | I43: 163.33 | J43: Eligible | K43: Physical Service Visit | L43: TJX server-refresh work completed; payment breakdown confirmed at $163.33. | M43: User chronology + Gmail WO assignment and payment breakdown | N43: EVT-0080
A44: Visual Analytics

Sheet Service Events
A1: Event # | B1: Physical Visit ID | C1: Service Date | D1: Weekday | E1: Workweek # | F1: MY_MONTH | G1: Client ID | H1: Client | I1: Site Name | J1: Address | K1: City | L1: State | M1: ZIP | N1: Jurisdiction | O1: Location Key | P1: Status | Q1: Visit Type | R1: Work Order Count | S1: Work Orders | T1: Confirmed Revenue | U1: Revenue Eligibility | V1: Notes | W1: Source / Evidence | X1: Financial Scope | Y1: Financial Exclusion Reason | Z1: Breakdown Expected
A2: 1 | B2: EVT-0001 | C2: 46132 | D2: Monday | E2: 1 | F2: MY_MONTH 1 | G2: CL-001 | H2: Macy's | I2: Macy's | K2: Fairfax | L2: Virginia | N2: VA | O2: Fairfax|VA | P2: Completed | Q2: Physical Service Visit | R2: 1 | S2: 5847113 | T2: 90 | U2: Eligible | V2: VA model from prior approved calculation. | W2: Timeline + Service Calendar + Canonical Ledger | X2: Included | Z2: Yes
A3: 2 | B3: EVT-0002 | C3: 46133 | D3: Tuesday | E3: 1 | F3: MY_MONTH 1 | G3: CL-002 | H3: Bloomingdale's | I3: Bloomingdale's | K3: Tysons | L3: Virginia | N3: VA | O3: Tysons|VA | P3: Completed | Q3: Physical Service Visit | R3: 1 | S3: 5860365 | T3: 344 | U3: Eligible | V3: 8-hour assist tech; effective $43/hr. | W3: Timeline + Service Calendar + Canonical Ledger | X3: Included | Z3: Yes
A4: 3 | B4: EVT-0003 | C4: 46134 | D4: Wednesday | E4: 1 | F4: MY_MONTH 1 | G4: CL-002 | H4: Bloomingdale's | I4: Bloomingdale's | K4: Tysons | L4: Virginia | N4: VA | O4: Tysons|VA | P4: Completed | Q4: Physical Service Visit | R4: 1 | S4: 5860393 | T4: 344 | U4: Eligible | V4: 8-hour assist tech; effective $43/hr. | W4: Timeline + Service Calendar + Canonical Ledger | X4: Included | Z4: Yes
A5: 4 | B5: EVT-0004 | C5: 46135 | D5: Thursday | E5: 1 | F5: MY_MONTH 1 | G5: CL-001 | H5: Macy's | I5: Macy's | K5: Frederick | L5: Maryland | N5: MD | O5: Frederick|MD | P5: Completed | Q5: Physical Service Visit | R5: 1 | S5: 5874484 | T5: 180 | U5: Eligible | V5: Maryland revenue included; hours inferred at $45/hr. | W5: Timeline + Service Calendar + Canonical Ledger | X5: Included | Z5: Yes
A6: 5 | B6: EVT-0005 | C6: 46136 | D6: Friday | E6: 1 | F6: MY_MONTH 1 | G6: CL-003 | H6: Hampton Inn & Suites | I6: Hampton Inn & Suites | K6: Washington | L6: Washington, DC | N6: DC | O6: Washington|DC | P6: Completed | Q6: Physical Service Visit | R6: 1 | S6: 5876589 | T6: 50 | U6: Eligible | V6: DC flat/equivalent event. | W6: Timeline + Service Calendar + Canonical Ledger | X6: Included | Z6: Yes
A7: 6 | B7: EVT-0006 | C7: 46139 | D7: Monday | E7: 2 | F7: MY_MONTH 1 | G7: CL-001 | H7: Macy's | I7: Macy's | K7: Frederick | L7: Maryland | N7: MD | O7: Frederick|MD | P7: Completed | Q7: Physical Service Visit | R7: 1 | S7: 5874982 | T7: 180 | U7: Eligible | V7: Maryland revenue included; hours inferred at $45/hr. | W7: Timeline + Service Calendar + Canonical Ledger | X7: Included | Z7: Yes
A8: 7 | B8: EVT-0007 | C8: 46141 | D8: Wednesday | E8: 2 | F8: MY_MONTH 1 | G8: CL-004 | H8: Davis Polk & Wardwell | I8: Davis Polk & Wardwell | K8: Washington | L8: Washington, DC | N8: DC | O8: Washington|DC | P8: Completed | Q8: Physical Service Visit | R8: 1 | S8: 5876638 | T8: 50 | U8: Eligible | V8: DC flat/equivalent event. | W8: Timeline + Service Calendar + Canonical Ledger | X8: Included | Z8: Yes
A9: 8 | B9: EVT-0008 | C9: 46141 | D9: Wednesday | E9: 2 | F9: MY_MONTH 1 | G9: CL-005 | H9: Hebrew Home of Greater Washington | I9: Hebrew Home of Greater Washington | K9: North Bethesda | L9: Maryland | N9: MD | O9: North Bethesda|MD | P9: Completed | Q9: Physical Service Visit | R9: 1 | S9: 5878985 | T9: 45 | U9: Eligible | V9: Maryland revenue included. | W9: Timeline + Service Calendar + Canonical Ledger | X9: Included | Z9: Yes
A10: 9 | B10: EVT-0009 | C10: 46142 | D10: Thursday | E10: 2 | F10: MY_MONTH 1 | G10: CL-006 | H10: 7-Eleven | I10: 7-Eleven | K10: Baltimore | L10: Maryland | N10: MD | O10: Baltimore|MD | P10: Completed | Q10: Physical Service Visit | R10: 1 | S10: UNRESOLVED-E009 | T10: 135 | U10: Eligible | V10: User-authoritative financial correction: 3 hours × $45 = $135.00. | W10: User-authoritative correction 2026-07-26 | X10: Included | Z10: Yes
A11: 10 | B11: EVT-0010 | C11: 46147 | D11: Tuesday | E11: 3 | F11: MY_MONTH 1 | G11: CL-007 | H11: Giant Food Stores | I11: Giant Food Stores | K11: Hanover | L11: Pennsylvania | N11: PA | O11: Hanover|PA | P11: Completed | Q11: Physical Service Visit | R11: 1 | S11: 5882097 | T11: 212.5 | U11: Eligible | V11: Corrected: Hanover PA WO 5882097. | W11: Timeline + Service Calendar + Canonical Ledger | X11: Included | Z11: Yes
A12: 11 | B12: EVT-0011 | C12: 46153 | D12: Monday | E12: 4 | F12: MY_MONTH 1 | G12: CL-008 | H12: Food Lion | I12: Food Lion | K12: Leesburg | L12: Virginia | N12: VA | O12: Leesburg|VA | P12: Completed | Q12: Physical Service Visit | R12: 1 | S12: 5884987 | T12: 157.5 | U12: Eligible | V12: VA model uses payment breakdown amount. | W12: Timeline + Service Calendar + Canonical Ledger | X12: Included | Z12: Yes
A13: 12 | B13: EVT-0012 | C13: 46154 | D13: Tuesday | E13: 4 | F13: MY_MONTH 1 | G13: CL-009 | H13: Weis Markets | I13: Weis Markets | K13: Chambersburg | L13: Pennsylvania | N13: PA | O13: Chambersburg|PA | P13: Completed | Q13: Physical Service Visit | R13: 1 | S13: 5884369 | T13: 85 | U13: Eligible | V13: User approved 2-hour $42.50/hr equivalent. | W13: Timeline + Service Calendar + Canonical Ledger | X13: Included | Z13: Yes
... A60: 59 | B60: EVT-0059 | C60: 46210 | D60: Tuesday | E60: 12 | F60: MY_MONTH 3 | G60: CL-026 | H60: Dunkin | I60: Dunkin | K60: Aberdeen | L60: Maryland | N60: MD | O60: Aberdeen|MD | P60: Completed | Q60: Physical Service Visit | R60: 1 | S60: 5900830 | T60: 250 | U60: Eligible | V60: Dunkin Aberdeen completed; 3 lanes + K27 kiosk; extended Verifone validation call; payment breakdown $250.00; ACH pending. | W60: Timeline + Service Calendar + Canonical Ledger | X60: Included | Z60: Yes
A61: 60 | B61: EVT-0060 | C61: 46211 | D61: Wednesday | E61: 12 | F61: MY_MONTH 3 | G61: CL-027 | H61: Carvana | I61: Carvana | K61: Baltimore | L61: Maryland | N61: MD | O61: Baltimore|MD | P61: Completed | Q61: Same-site multi-WO visit | R61: 2 | S61: 5912364 / 5914049 | U61: Excluded | V61: One physical Carvana visit with two work orders: 5914049 firmware resolved 98.00.0C; 5912364 cyan cleanup/blank-page escalation documented. One event, two WOs, $130 total. | W61: Timeline + Service Calendar + Canonical Ledger | X61: Included | Z61: Yes
A62: 61 | B62: EVT-0061 | C62: 46212 | D62: Thursday | E62: 12 | F62: MY_MONTH 3 | G62: CL-020 | H62: TJ Maxx | I62: TJ Maxx | K62: Germantown | L62: Maryland | N62: MD | O62: Germantown|MD | P62: Completed | Q62: Physical Service Visit | R62: 1 | S62: 5909344 | T62: 194.99 | U62: Eligible | V62: TJ Maxx Germantown server refresh completed 2026-07-09. Payment breakdown confirmed at $194.99 with no deductions; expected payment 2026-07-23; ACH pending. | W62: Gmail payment breakdown 2026-07-11 + Timeline + Service Calendar | X62: Included | Z62: Yes
A63: 62 | B63: EVT-0062 | C63: 46212 | D63: Thursday | E63: 12 | F63: MY_MONTH 3 | G63: CL-020 | H63: TJ Maxx | I63: TJ Maxx | K63: Martinsburg | L63: West Virginia | N63: WV | O63: Martinsburg|WV | P63: Completed | Q63: Physical Service Visit | R63: 1 | S63: 5913868 | T63: 100.83 | U63: Eligible | V63: TJ Maxx Martinsburg completed 2026-07-09. Negotiated $150; payment breakdown received for $100.83; variance -$49.17; expected payment 2026-07-23. | W63: Timeline + Service Calendar + Canonical Ledger | X63: Included | Z63: Yes
A64: 63 | B64: EVT-0063 | C64: 46216 | D64: Monday | E64: 13 | F64: MY_MONTH 3 | G64: CL-022 | H64: Marshalls | I64: Marshalls — Hunt Valley Town Center | J64: 118 Shawan Rd Ste W | K64: Cockeysville | L64: Maryland | M64: 21030 | N64: MD | O64: Cockeysville|MD | P64: Completed | Q64: Physical Service Visit | R64: 1 | S64: 5909368 | U64: Excluded | V64: Marshalls Cockeysville server refresh completed. Replacement store server installed and validated; front-left sliding rail was corrected during installation. Hourly rate $40; final breakdown pending. | W64: 5909368_MarshallsCockeysville.pdf + user-authoritative completion 2026-07-13 | X64: Included | Z64: Yes
A65: 64 | B65: EVT-0064 | C65: 46216 | D65: Monday | E65: 13 | F65: MY_MONTH 3 | G65: CL-022 | H65: Marshalls | I65: Marshalls 0764 | J65: 17646 Garland Groh Blvd | K65: Hagerstown | L65: Maryland | M65: 21740 | N65: MD | O65: Hagerstown|MD | P65: Completed | Q65: Physical Service Visit | R65: 1 | S65: 5916961 | U65: Excluded | V65: Marshalls Hagerstown Register 2 M440 replacement completed. Arrived 12:55 PM; extended onsite time was caused by support unavailability and incorrect IP/gateway values in the ticket. Barrister confirmed documented onsite hours would be paid at $55/hour. Final breakdown pending. | W65: 5916961_MarshallsHagerstown.pdf + user-authoritative completion and onsite timeline 2026-07-13 | X65: Included | Z65: Yes
A66: 65 | B66: EVT-0065 | C66: 46216 | D66: Monday | E66: 13 | F66: MY_MONTH 3 | G66: CL-016 | H66: HomeGoods | I66: HomeGoods 0652 | J66: 606 Quince Orchard Road | K66: Gaithersburg | L66: Maryland | M66: 20878 | N66: MD | O66: Gaithersburg|MD | P66: Completed | Q66: Physical Service Visit | R66: 1 | S66: 5917407 | T66: 129.16 | U66: Eligible | V66: Payment breakdown confirmed at $129.16. | W66: User-verified payment breakdown record | X66: Included | Z66: Yes
A67: 66 | B67: EVT-0066 | C67: 46217 | D67: Tuesday | E67: 13 | F67: MY_MONTH 3 | G67: CL-020 | H67: TJ Maxx | I67: TJ Maxx — Tollgate Mall | J67: 615 Bel Air Road | K67: Bel Air | L67: Maryland | M67: 21014 | N67: MD | O67: Bel Air|MD | P67: Completed | Q67: Physical Service Visit | R67: 1 | S67: 5909385 | U67: Excluded | V67: TJ Maxx Bel Air server refresh completed. Installed the NextGen 11 server in available rack space after labeling the VH1 and VH2 cabling. NCR completed the HDD/data migration and the replacement server came online successfully. All required functions were validated. VH1 was decommissioned, boxed, labeled, and prepared for return with shipping labels. No Mood Media, Tripplite, or Frontline equipment was installed. New server S/N 2M2D3000F3; asset tag A929164. MOD Lori Fox. Hourly rate $45; final payment breakdown pending. | W67: WO 5909385 RFS + FastField/photo evidence + user-authoritative completion 2026-07-14 | X67: Included | Z67: Yes
A68: 67 | B68: EVT-0067 | C68: 46217 | D68: Tuesday | E68: 13 | F68: MY_MONTH 3 | G68: CL-026 | H68: Dunkin | I68: Dunkin Donuts #342406 | J68: 645 S. Philadelphia Blvd | K68: Aberdeen | L68: Maryland | M68: 21001 | N68: MD | O68: Aberdeen|MD | P68: Completed | Q68: Physical Service Visit | R68: 1 | S68: 5914898 | T68: 183.74 | U68: Eligible | V68: Dunkin Aberdeen return visit completed. Continued troubleshooting the K27 kiosk issue. Verifone kept the technician on an extended support call and contacted the third-party kiosk provider, which advised that no technician was available and the issue required escalation to the United Service Desk. At the United Service Desk's direction, additional troubleshooting was completed, including rebooting POS 1 despite the issue remaining isolated to Kiosk 1. The unresolved kiosk issue was escalated for additional follow-up/dispatch, and support formally released the technician from site. Payment breakdown confirmed at $183.74 with no deductions; expected payment 2026-07-28; ACH pending. | W68: WO 5914898 RFS + user-authoritative completion + Gmail payment breakdown 2026-07-14 | X68: Included | Z68: Yes
A69: 68 | B69: EVT-0068 | C69: 46218 | D69: Wednesday | E69: 13 | F69: MY_MONTH 3 | G69: CL-026 | H69: Dunkin | I69: Dunkin — Fallston | K69: Fallston | L69: Maryland | N69: MD | O69: Fallston|MD | P69: Completed | Q69: Physical Service Visit | R69: 1 | S69: 5900854 | T69: 350 | U69: Eligible | V69: Dunkin Fallston visit completed. Payment breakdown confirmed at $350.00; Speed ACH expected 2026-07-29. | W69: User-authoritative completion + Gmail payment breakdown | X69: Included | Z69: Yes
A70: 69 | B70: EVT-0069 | C70: 46219 | D70: Thursday | E70: 13 | F70: MY_MONTH 3 | G70: CL-020 | H70: TJ Maxx | I70: TJ Maxx — Columbia | K70: Columbia | L70: Maryland | N70: MD | O70: Columbia|MD | P70: Completed | Q70: Physical Service Visit | R70: 1 | S70: 5909418 | T70: 180 | U70: Eligible | V70: TJ Maxx Columbia visit completed. Hourly rate $40.00; final payment breakdown pending. Payment breakdown confirmed at $180.00 with no deductions; expected payment 2026-07-30. | W70: User-authoritative completion + ticket details + Gmail payment breakdown | X70: Included | Z70: Yes
A71: 70 | B71: EVT-0070 | C71: 46219 | D71: Thursday | E71: 13 | F71: MY_MONTH 3 | G71: CL-007 | H71: Giant Food Stores | I71: Giant Food — Olney | K71: Olney | L71: Maryland | N71: MD | O71: Olney|MD | P71: Completed | Q71: Physical Service Visit | R71: 1 | S71: 5918899 | T71: 103.33 | U71: Eligible | V71: Giant Food Olney HCL network troubleshooting completed and technician released. Roof and server-room cabling were traced and tested; final payment breakdown pending. Payment breakdown confirmed at $103.33 with no deductions; expected payment 2026-07-30. | W71: User-authoritative completion + onsite troubleshooting notes + Gmail payment breakdown | X71: Included | Z71: Yes
A72: 71 | B72: EVT-0071 | C72: 46220 | D72: Friday | E72: 13 | F72: MY_MONTH 3 | G72: CL-028 | H72: WeWork | I72: WeWork DC18 | J72: 200 Massachusetts Ave NW | K72: Washington | L72: Washington, DC | M72: 20001 | N72: DC | O72: Washington|DC | P72: Completed | Q72: Physical Service Visit | R72: 1 | S72: 5918348 | T72: 90 | U72: Eligible | V72: User-authoritative confirmed amount: 2 hours × $45 = $90.00. | W72: User-authoritative correction 2026-07-26 | X72: Included | Z72: Yes
A73: 72 | B73: EVT-0072 | C73: 46220 | D73: Friday | E73: 13 | F73: MY_MONTH 3 | G73: CL-029 | H73: Miramar | I73: Hebrew Home of Greater Washington | K73: North Bethesda | L73: Maryland | N73: MD | O73: North Bethesda|MD | P73: Completed | Q73: Physical Service Visit | R73: 1 | S73: 5913115 | T73: 50 | U73: Eligible | V73: Miramar ticket at Hebrew Home closed by the client system after technician arrival and escalation. Promised flat rate $50.00 Speed ACH; completed chronology, but compensation classification and payment breakdown remain unresolved. Payment breakdown confirmed at $50.00 with no deductions; expected payment 2026-07-31. | W73: WO 5913115 + user-authoritative closed-ticket completion + Omnicare/Eric call notes + Gmail payment breakdown | X73: Included | Z73: Yes
A74: 73 | B74: EVT-0073 | C74: 46223 | D74: Monday | E74: 14 | F74: MY_MONTH 4 | G74: CL-030 | H74: Homesense | I74: Homesense TJH0030 | J74: 10220 Mill Run Cir | K74: Owings Mills | L74: Maryland | M74: 21117 | N74: MD | O74: Owings Mills|MD | P74: Completed | Q74: Physical Service Visit | R74: 1 | S74: 5906821 | T74: 180 | U74: Eligible | V74: VH2 server deinstall completed. Arrived 5:30 AM; store opened 7:00 AM. Delay joining NCR Bridgeline/Teams support. NCR confirmed additional Music Mood Media and Lounge Mood Media replacement scope, but the box onsite did not contain the replacement players and store management could not locate them. Additional delay obtaining the FedEx waybill and MOD signature. VH2 was removed, packaged, documented, and prepared for return. Payment breakdown confirmed at $180.00; expected payment 2026-08-03. | W74: WO 5906821 RFS + onsite completion notes + Gmail payment breakdown | X74: Included | Z74: Yes
A75: 74 | B75: EVT-0074 | C75: 46223 | D75: Monday | E75: 14 | F75: MY_MONTH 4 | G75: CL-031 | H75: Autumn Lake Healthcare | I75: Autumn Lake at Baltimore Washington | J75: 313 Hospital Dr | K75: Glen Burnie | L75: Maryland | M75: 21061 | N75: MD | O75: Glen Burnie|MD | P75: Completed | Q75: Physical Service Visit | R75: 1 | S75: 5919707 | T75: 50 | U75: Eligible | V75: Customer/site no-show. Technician called both listed numbers and spoke with front desk; staff did not recognize Nina or the reported fax issue. Equipment could not be identified or accessed. Payment breakdown confirmed at $50.00 with no deductions. | W75: WO 5919707 RFS + user-authoritative completion/no-show notes + Gmail payment breakdown received 2026-07-21 | X75: Included | Z75: Yes
A76: 75 | B76: EVT-0075 | C76: 46223 | D76: Monday | E76: 14 | F76: MY_MONTH 4 | G76: CL-031 | H76: Autumn Lake Healthcare | I76: Autumn Lake at Glen Burnie — Rosemary Unit | J76: 7355 E Furnace Branch Rd | K76: Glen Burnie | L76: Maryland | M76: 21060 | N76: MD | O76: Glen Burnie|MD | P76: Completed | Q76: Physical Service Visit | R76: 1 | S76: 5920784 | T76: 50 | U76: Eligible | V76: New Sharp MX-B427W installed in the Rosemary Unit. Fax testing failed because of a facility fax-line issue. Technician contacted Omnicare and troubleshot with Wade, who confirmed the line requires repair and will coordinate next steps. Printer/fax installation was completed, work area and packaging were cleaned, and required form was completed and signed. Payment breakdown confirmed at $50.00; expected payment 2026-08-03. | W76: WO 5920784 RFS + signed installation form/photo + user completion + Gmail payment breakdown | X76: Included | Z76: Yes
A77: 76 | B77: EVT-0076 | C77: 46224 | D77: Tuesday | E77: 14 | F77: MY_MONTH 4 | G77: CL-022 | H77: Marshalls | I77: Marshalls — Owings Mills | K77: Owings Mills | L77: Maryland | N77: MD | O77: Owings Mills|MD | P77: Completed | Q77: Physical Service Visit | R77: 1 | S77: 5906834 | T77: 120 | U77: Eligible | V77: Payment breakdown confirmed at $120.00. | W77: User-verified payment breakdown record | X77: Included | Z77: Yes
A78: 77 | B78: EVT-0077 | C78: 46225 | D78: Wednesday | E78: 14 | F78: MY_MONTH 4 | G78: CL-022 | H78: Marshalls | I78: Marshalls — Towson | K78: Towson | L78: Maryland | N78: MD | O78: Towson|MD | P78: Completed | Q78: Physical Service Visit | R78: 1 | S78: UNRESOLVED-E077 | U78: Pending | V78: Completed visit; work-order and payment breakdown mapping pending. | W78: User-authoritative chronology correction | X78: Included | Z78: Yes
A79: 78 | B79: EVT-0078 | C79: 46225 | D79: Wednesday | E79: 14 | F79: MY_MONTH 4 | G79: CL-026 | H79: Dunkin | I79: Dunkin — Owings Mills | K79: Owings Mills | L79: Maryland | N79: MD | O79: Owings Mills|MD | P79: Completed | Q79: Physical Service Visit | R79: 1 | S79: 5900769 | T79: 160.29 | U79: Eligible | V79: Payment breakdown confirmed at $160.29. | W79: User-verified payment breakdown record | X79: Included | Z79: Yes
A80: 79 | B80: EVT-0079 | C80: 46225 | D80: Wednesday | E80: 14 | F80: MY_MONTH 4 | G80: CL-006 | H80: 7-Eleven | I80: 7-Eleven — Fallston | J80: 2400 Pleasantville Rd | K80: Fallston | L80: Maryland | M80: 21047 | N80: MD | O80: Fallston|MD | P80: Completed | Q80: Physical Service Visit | R80: 1 | S80: 5921549 | T80: 168.75 | U80: Eligible | V80: Digital menu board service completed. Payment breakdown confirmed at $168.75; no deductions. | W80: User chronology + Gmail WO assignment and payment breakdown | X80: Included | Z80: Yes
A81: 80 | B81: EVT-0080 | C81: 46226 | D81: Thursday | E81: 14 | F81: MY_MONTH 4 | G81: CL-022 | H81: Marshalls | I81: Marshalls — Westminster | J81: 200 Clifton Blvd, Suite C | K81: Westminster | L81: Maryland | M81: 21157 | N81: MD | O81: Westminster|MD | P81: Completed | Q81: Physical Service Visit | R81: 1 | S81: 5906863 | T81: 163.33 | U81: Eligible | V81: TJX server-refresh work completed. Payment breakdown confirmed at $163.33; no deductions. | W81: User chronology + Gmail WO assignment and payment breakdown | X81: Included | Z81: Yes
A82: 81 | B82: EVT-0081 | C82: 46226 | D82: Thursday | E82: 14 | F82: MY_MONTH 4 | G82: CL-016 | H82: HomeGoods | I82: HomeGoods — Fairfax | K82: Fairfax | L82: Virginia | N82: VA | O82: Fairfax|VA | P82: Completed | Q82: Physical Service Visit | R82: 1 | S82: 5922660 | T82: 125 | U82: Eligible | V82: Power USB cable service completed. Payment breakdown confirmed at $125.00; no deductions. | W82: User chronology + Gmail ETA and payment breakdown | X82: Included | Z82: Yes
A83: 82 | B83: EVT-0082 | C83: 46226 | D83: Thursday | E83: 14 | F83: MY_MONTH 4 | G83: CL-020 | H83: TJ Maxx | I83: TJ Maxx — Alexandria | K83: Alexandria | L83: Virginia | N83: VA | O83: Alexandria|VA | P83: Completed | Q83: Physical Service Visit | R83: 1 | S83: 5922683 | T83: 110 | U83: Eligible | V83: BERG adapter service completed. Payment breakdown confirmed at $110.00; no deductions. | W83: User chronology + Gmail ETA and payment breakdown | X83: Included | Z83: Yes
A84: 83 | B84: EVT-0083 | C84: 46227 | D84: Friday | E84: 14 | F84: MY_MONTH 4 | G84: CL-027 | H84: Carvana | I84: Carvana — Baltimore | J84: 4901 Holabird Ave | K84: Baltimore | L84: Maryland | M84: 21224 | N84: MD | O84: Baltimore|MD | P84: Completed | Q84: Physical Service Visit | R84: 1 | S84: 5919318 | T84: 65 | U84: Eligible | V84: HP Color LaserJet Managed MFP fuser replaced and ticket completed. Payment breakdown confirmed at $65.00; no deductions. | W84: User completion + Gmail WO assignment and payment breakdown | X84: Included | Z84: Yes
A85: 84 | B85: EVT-0084 | C85: 46227 | D85: Friday | E85: 14 | F85: MY_MONTH 4 | G85: CL-007 | H85: Giant Food Stores | I85: Giant Food — Wheaton | J85: 2900 University Boulevard West | K85: Wheaton | L85: Maryland | M85: 20902 | N85: MD | O85: Wheaton|MD | P85: Completed | Q85: Physical Service Visit | R85: 1 | S85: 5922604 | U85: Pending | V85: Cradlepoint outage resolved after replacing the rooftop unit and PoE injector; Port 42 restored and site operational. Payment breakdown pending. | W85: User-authoritative completion + Gmail WO assignment and closeout correspondence | X85: Included | Z85: Yes
A86: 85 | C86: 46230 | H86: Dunkin | K86: Bel Air | L86: Maryland | N86: MD | P86: Completed
...

Sheet Work Orders & Ledger
A1: Ledger Record ID | B1: Work Order # | C1: Event # | D1: Candidate Event(s) | E1: Client ID | F1: Client | G1: Service Date | H1: Weekday | I1: Site Name | J1: Address | K1: City | L1: State | M1: ZIP | N1: Jurisdiction | O1: Location Key | P1: Agreed Amount | Q1: Pay Type | R1: Breakdown Confirmed | S1: Breakdown Amount | T1: Breakdown Date | U1: Expected Payment Date | V1: ACH Confirmed | W1: ACH Amount | X1: ACH Date | Y1: Variance | Z1: Reconciliation Status | AA1: Mapping Status | AB1: Alias / Related WO | AC1: Notes | AD1: Source / Evidence
A2: LED-0001 | B2: 5847113 | C2: 1 | E2: CL-001 | F2: Macy's | G2: 46132 | H2: Monday | I2: Macy's | K2: Fairfax | L2: Virginia | N2: VA | O2: Fairfax|VA | R2: Yes | S2: 90 | V2: Yes | W2: 90 | Z2: Complete with note | AA2: Unique | AC2: VA model from prior approved calculation. | AD2: WO Alias Index + Canonical Ledger
A3: LED-0002 | B3: 5860365 | C3: 2 | E3: CL-002 | F3: Bloomingdale's | G3: 46133 | H3: Tuesday | I3: Bloomingdale's | K3: Tysons | L3: Virginia | N3: VA | O3: Tysons|VA | R3: Yes | S3: 344 | V3: Yes | W3: 344 | Z3: Complete | AA3: Unique | AC3: 8-hour assist tech; effective $43/hr. | AD3: WO Alias Index + Canonical Ledger
A4: LED-0003 | B4: 5860393 | C4: 3 | E4: CL-002 | F4: Bloomingdale's | G4: 46134 | H4: Wednesday | I4: Bloomingdale's | K4: Tysons | L4: Virginia | N4: VA | O4: Tysons|VA | R4: Yes | S4: 344 | V4: Yes | W4: 344 | Z4: Complete | AA4: Unique | AC4: 8-hour assist tech; effective $43/hr. | AD4: WO Alias Index + Canonical Ledger
A5: LED-0004 | B5: 5874484 | C5: 4 | E5: CL-001 | F5: Macy's | G5: 46135 | H5: Thursday | I5: Macy's | K5: Frederick | L5: Maryland | N5: MD | O5: Frederick|MD | R5: Yes | S5: 180 | V5: Yes | W5: 180 | Z5: Complete | AA5: Unique | AC5: Maryland revenue included; hours inferred at $45/hr. | AD5: WO Alias Index + Canonical Ledger
A6: LED-0005 | B6: 5876589 | C6: 5 | E6: CL-003 | F6: Hampton Inn & Suites | G6: 46136 | H6: Friday | I6: Hampton Inn & Suites | K6: Washington | L6: Washington, DC | N6: DC | O6: Washington|DC | R6: Yes | S6: 50 | V6: Yes | W6: 50 | Z6: Complete | AA6: Unique | AC6: DC flat/equivalent event. | AD6: WO Alias Index + Canonical Ledger
A7: LED-0006 | B7: 5874982 | C7: 6 | E7: CL-001 | F7: Macy's | G7: 46139 | H7: Monday | I7: Macy's | K7: Frederick | L7: Maryland | N7: MD | O7: Frederick|MD | R7: Yes | S7: 180 | V7: Yes | W7: 180 | Z7: Complete | AA7: Unique | AC7: Maryland revenue included; hours inferred at $45/hr. | AD7: WO Alias Index + Canonical Ledger
A8: LED-0007 | B8: 5876638 | C8: 7 | E8: CL-004 | F8: Davis Polk & Wardwell | G8: 46141 | H8: Wednesday | I8: Davis Polk & Wardwell | K8: Washington | L8: Washington, DC | N8: DC | O8: Washington|DC | R8: Yes | S8: 50 | V8: Yes | W8: 50 | Z8: Complete | AA8: Unique | AC8: DC flat/equivalent event. | AD8: WO Alias Index + Canonical Ledger
A9: LED-0008 | B9: 5878985 | C9: 8 | E9: CL-005 | F9: Hebrew Home of Greater Washington | G9: 46141 | H9: Wednesday | I9: Hebrew Home of Greater Washington | K9: North Bethesda | L9: Maryland | N9: MD | O9: North Bethesda|MD | R9: Yes | S9: 45 | V9: Yes | W9: 45 | Z9: Complete | AA9: Unique | AC9: Maryland revenue included. | AD9: WO Alias Index + Canonical Ledger
A10: LED-0009 | B10: UNRESOLVED-E009 | C10: 9 | E10: CL-006 | F10: 7-Eleven | G10: 46142 | H10: Thursday | I10: 7-Eleven | K10: Baltimore | L10: Maryland | N10: MD | O10: Baltimore|MD | Q10: User-confirmed compensation | R10: Yes | S10: 135 | T10: 46229 | V10: No | Y10: 0 | Z10: ACH missing | AA10: Unique | AC10: User-authoritative financial correction: 3 hours × $45 = $135.00. | AD10: User-authoritative correction 2026-07-26
A11: LED-0010 | B11: 5882097 | C11: 10 | E11: CL-007 | F11: Giant Food Stores | G11: 46147 | H11: Tuesday | I11: Giant Food Stores | K11: Hanover | L11: Pennsylvania | N11: PA | O11: Hanover|PA | R11: Yes | S11: 212.5 | V11: Yes | W11: 212.5 | Z11: Complete | AA11: Unique | AC11: Corrected: Hanover PA WO 5882097. | AD11: WO Alias Index + Canonical Ledger
A12: LED-0011 | B12: 5884987 | C12: 11 | E12: CL-008 | F12: Food Lion | G12: 46153 | H12: Monday | I12: Food Lion | K12: Leesburg | L12: Virginia | N12: VA | O12: Leesburg|VA | R12: Yes | S12: 157.5 | V12: Yes | W12: 157.5 | Z12: Complete with note | AA12: Unique | AC12: VA model uses payment breakdown amount. | AD12: WO Alias Index + Canonical Ledger
A13: LED-0012 | B13: 5884369 | C13: 12 | E13: CL-009 | F13: Weis Markets | G13: 46154 | H13: Tuesday | I13: Weis Markets | K13: Chambersburg | L13: Pennsylvania | N13: PA | O13: Chambersburg|PA | R13: Yes | S13: 85 | V13: Yes | W13: 85 | Z13: Complete | AA13: Unique | AC13: User approved 2-hour $42.50/hr equivalent. | AD13: WO Alias Index + Canonical Ledger
A14: LED-0013 | B14: 5885429 | C14: 13 | E14: CL-010 | F14: Office of MD Senator Chris Van Hollen | G14: 46155 | H14: Wednesday | I14: Office of MD Senator Chris Van Hollen | K14: Rockville | L14: Maryland | N14: MD | O14: Rockville|MD | R14: Yes | S14: 50 | V14: Yes | W14: 50 | Z14: Complete | AA14: Unique | AC14: Maryland revenue included; Senate model estimated at $40/hr. | AD14: WO Alias Index + Canonical Ledger
A15: LED-0014 | B15: UNRESOLVED-E014 | C15: 14 | E15: CL-011 | F15: Residential – Annapolis Neck, MD | G15: 46155 | H15: Wednesday | I15: Residential | K15: Annapolis Neck | L15: Maryland | N15: MD | O15: Annapolis Neck|MD | Q15: User-confirmed compensation | R15: Yes | S15: 25 | T15: 46229 | V15: No | Y15: 0 | Z15: ACH missing | AA15: Unique | AC15: User-authoritative no-show compensation: $25.00. | AD15: User-authoritative correction 2026-07-26
A16: LED-0015 | B16: 5886658 | C16: 15 | E16: CL-012 | F16: Verizon | G16: 46156 | H16: Thursday | I16: Verizon | K16: College Park | L16: Maryland | N16: MD | O16: College Park|MD | R16: Yes | S16: 75 | V16: Yes | W16: 75 | Z16: Complete | AA16: Unique | AC16: Maryland revenue included; hours inferred. | AD16: WO Alias Index + Canonical Ledger
A17: LED-0016 | B17: 5887090 | C17: 16 | E17: CL-013 | F17: Atrium Village | G17: 46157 | H17: Friday | I17: Atrium Village | K17: Owings Mills | L17: Maryland | N17: MD | O17: Owings Mills|MD | R17: Yes | S17: 45 | V17: Yes | W17: 45 | Z17: Complete | AA17: Unique | AC17: Maryland revenue included. | AD17: WO Alias Index + Canonical Ledger
A18: LED-0017 | B18: 5887094 | C18: 17 | E18: CL-014 | F18: Maryland Baptist Age Home | G18: 46161 | H18: Tuesday | I18: Maryland Baptist Age Home | K18: Baltimore | L18: Maryland | N18: MD | O18: Baltimore|MD | R18: Yes | S18: 50 | V18: Yes | W18: 50 | Z18: Complete | AA18: Unique | AC18: Maryland revenue included. | AD18: WO Alias Index + Canonical Ledger
A19: LED-0018 | B19: 5889356 | C19: 18 | E19: CL-015 | F19: Under Armour | G19: 46162 | H19: Wednesday | I19: Under Armour Day 1 | K19: Hanover | L19: Maryland | N19: MD | O19: Hanover|MD | R19: Yes | S19: 106.67 | V19: Yes | W19: 106.67 | Z19: Complete | AA19: Unique | AC19: Under Armour Day 1 split; total UA rounded to $260 with Day 2. | AD19: WO Alias Index + Canonical Ledger
A20: LED-0019 | B20: 5889356-D2 | C20: 19 | E20: CL-015 | F20: Under Armour | G20: 46163 | H20: Thursday | I20: Under Armour Day 2 | K20: Hanover | L20: Maryland | N20: MD | O20: Hanover|MD | R20: Yes | S20: 153.33 | V20: Yes | W20: 153.33 | Z20: Complete | AA20: Unique | AC20: Under Armour Day 2 split; total UA rounded to $260 with Day 1. | AD20: WO Alias Index + Canonical Ledger
A21: LED-0020 | B21: 5890220 | C21: 20 | E21: CL-007 | F21: Giant Food Stores | G21: 46163 | H21: Thursday | I21: Giant / Martin's | K21: Red Lion | L21: Pennsylvania | N21: PA | O21: Red Lion|PA | R21: Yes | S21: 112.5 | V21: Yes | W21: 112.5 | Z21: Complete | AA21: Unique | AC21: Corrected: Red Lion PA WO 5890220. | AD21: WO Alias Index + Canonical Ledger
A22: LED-0021 | B22: 5892123 | C22: 21 | E22: CL-008 | F22: Food Lion | G22: 46168 | H22: Tuesday | I22: Food Lion | K22: Middle River | L22: Maryland | N22: MD | O22: Middle River|MD | R22: Yes | S22: 97.91 | V22: Yes | W22: 97.91 | Z22: Complete | AA22: Unique | AC22: Maryland revenue included; hours inferred. | AD22: WO Alias Index + Canonical Ledger
A23: LED-0022 | B23: 5889718 | C23: 22 | E23: CL-016 | F23: HomeGoods | G23: 46168 | H23: Tuesday | I23: HomeGoods | K23: Gaithersburg | L23: Maryland | N23: MD | O23: Gaithersburg|MD | R23: Yes | S23: 50 | V23: Yes | W23: 50 | Z23: Complete | AA23: Unique | AC23: Maryland revenue included; hours inferred. | AD23: WO Alias Index + Canonical Ledger
A24: LED-0023 | B24: UNRESOLVED-E023 | C24: 23 | E24: CL-017 | F24: Joint Base Andrews | G24: 46169 | H24: Wednesday | I24: Joint Base Andrews | K24: Andrews AFB | L24: Maryland | N24: MD | O24: Andrews AFB|MD | Q24: User-confirmed compensation | R24: Yes | S24: 50 | T24: 46229 | V24: No | Y24: 0 | Z24: ACH missing | AA24: Unique | AC24: User-authoritative first-hour no-show compensation: $50.00. | AD24: User-authoritative correction 2026-07-26
A25: LED-0024 | B25: USDA-SPECIAL-E024 | C25: 24 | E25: CL-018 | F25: USDA | G25: 46169 | H25: Wednesday | I25: USDA Day 1 | K25: Washington | L25: Washington, DC | N25: DC | O25: Washington|DC | R25: Yes | S25: 200 | V25: Yes | W25: 200 | Z25: Complete | AA25: DUPLICATE / REVIEW | AC25: USDA corrected day allocation: $200 / 5 hrs @ $40/hr. | AD25: WO Alias Index + Canonical Ledger
A26: LED-0025 | B26: UNRESOLVED-E025 | C26: 25 | E26: CL-019 | F26: PepsiCo | G26: 46170 | H26: Thursday | I26: PepsiCo | K26: Cheverly | L26: Maryland | N26: MD | O26: Cheverly|MD | Q26: User-confirmed compensation | R26: Yes | S26: 50 | T26: 46229 | V26: No | Y26: 0 | Z26: ACH missing | AA26: Unique | AC26: User-authoritative first-hour no-show compensation: $50.00. | AD26: User-authoritative correction 2026-07-26
A27: LED-0026 | B27: USDA-SPECIAL-E026 | C27: 26 | E27: CL-018 | F27: USDA | G27: 46170 | H27: Thursday | I27: USDA Day 2 | K27: Washington | L27: Washington, DC | N27: DC | O27: Washington|DC | R27: Yes | S27: 175 | V27: Yes | W27: 175 | Z27: Complete | AA27: DUPLICATE / REVIEW | AC27: USDA corrected day allocation: $175 / 4.375 hrs @ $40/hr. | AD27: WO Alias Index + Canonical Ledger
A28: LED-0027 | B28: USDA-SPECIAL-E027 | C28: 27 | E28: CL-018 | F28: USDA | G28: 46174 | H28: Monday | I28: USDA Day 3 | K28: Washington | L28: Washington, DC | N28: DC | O28: Washington|DC | R28: Yes | S28: 320 | V28: Yes | W28: 320 | Z28: Complete | AA28: DUPLICATE / REVIEW | AC28: USDA corrected day allocation: $320 / 8 hrs @ $40/hr. | AD28: WO Alias Index + Canonical Ledger
A29: LED-0028 | B29: USDA-SPECIAL-E028 | C29: 28 | E29: CL-018 | F29: USDA | G29: 46175 | H29: Tuesday | I29: USDA Day 4 | K29: Washington | L29: Washington, DC | N29: DC | O29: Washington|DC | R29: Yes | S29: 320 | V29: Yes | W29: 320 | Z29: Complete | AA29: DUPLICATE / REVIEW | AC29: USDA corrected day allocation: $320 / 8 hrs @ $40/hr. | AD29: WO Alias Index + Canonical Ledger
A30: LED-0029 | B30: USDA-SPECIAL-E029 | C30: 29 | E30: CL-018 | F30: USDA | G30: 46176 | H30: Wednesday | I30: USDA Day 5 | K30: Washington | L30: Washington, DC | N30: DC | O30: Washington|DC | R30: Yes | S30: 200 | V30: Yes | W30: 200 | Z30: Complete | AA30: DUPLICATE / REVIEW | AC30: USDA corrected day allocation: $200 / 5 hrs @ $40/hr. | AD30: WO Alias Index + Canonical Ledger
A31: LED-0030 | B31: 5896733 | C31: 30 | E31: CL-020 | F31: TJ Maxx | G31: 46176 | H31: Wednesday | I31: TJ Maxx | K31: Rockville | L31: Maryland | N31: MD | O31: Rockville|MD | R31: Yes | S31: 96.66 | V31: Yes | W31: 96.66 | Z31: Complete | AA31: Unique | AC31: Event #30 TJ Maxx Rockville verified at $96.66. | AD31: WO Alias Index + Canonical Ledger
A32: LED-0031 | B32: USDA-SPECIAL-E031 | C32: 31 | E32: CL-018 | F32: USDA | G32: 46177 | H32: Thursday | I32: USDA Day 6 | K32: Washington | L32: Washington, DC | N32: DC | O32: Washington|DC | R32: Yes | S32: 140 | V32: Yes | W32: 140 | Z32: Complete | AA32: DUPLICATE / REVIEW | AC32: USDA corrected day allocation: $140 / 3.5 hrs @ $40/hr. | AD32: WO Alias Index + Canonical Ledger
A33: LED-0032 | B33: 5898007 | C33: 32 | E33: CL-021 | F33: Hilton Garden Inn | G33: 46178 | H33: Friday | I33: Hilton Garden Inn | K33: Fairfax | L33: Virginia | N33: VA | O33: Fairfax|VA | R33: Yes | S33: 25 | V33: Yes | W33: 25 | Z33: Complete | AA33: Unique | AC33: VA Hilton Garden Inn historical row. | AD33: WO Alias Index + Canonical Ledger
A34: LED-0033 | B34: 5896039 | C34: 33 | E34: CL-005 | F34: Hebrew Home of Greater Washington | G34: 46178 | H34: Friday | I34: Hebrew Home of Greater Washington | K34: North Bethesda | L34: Maryland | N34: MD | O34: North Bethesda|MD | R34: Yes | S34: 50 | V34: Yes | W34: 50 | Z34: Complete | AA34: Unique | AC34: Maryland revenue included. | AD34: WO Alias Index + Canonical Ledger
A35: LED-0034 | B35: 5898904 | C35: 34 | E35: CL-020 | F35: TJ Maxx | G35: 46178 | H35: Friday | I35: TJ Maxx | K35: Annapolis | L35: Maryland | N35: MD | O35: Annapolis|MD | R35: Yes | S35: 70 | V35: Yes | W35: 70 | Z35: Complete | AA35: Unique | AC35: Maryland revenue included. | AD35: WO Alias Index + Canonical Ledger
A36: LED-0035 | B36: 5899056 | C36: 35 | E36: CL-022 | F36: Marshalls | G36: 46181 | H36: Monday | I36: Marshalls | K36: Dunkirk | L36: Maryland | N36: MD | O36: Dunkirk|MD | R36: Yes | S36: 70 | V36: Yes | W36: 70 | Z36: Complete | AA36: Unique | AC36: Payment breakdown reissued/verified; no financial change. | AD36: WO Alias Index + Canonical Ledger
A37: LED-0036 | B37: 5899295 | C37: 36 | E37: CL-003 | F37: Hampton Inn & Suites | G37: 46182 | H37: Tuesday | I37: Hampton Inn & Suites | K37: Edgewood | L37: Maryland | N37: MD | O37: Edgewood|MD | R37: Yes | S37: 65 | V37: Yes | W37: 65 | Z37: Complete | AA37: Unique | AC37: Maryland revenue included. | AD37: WO Alias Index + Canonical Ledger
A38: LED-0037 | B38: 5899715 | C38: 37 | E38: CL-016 | F38: HomeGoods | G38: 46182 | H38: Tuesday | I38: HomeGoods | K38: Sterling | L38: Virginia | N38: VA | O38: Sterling|VA | R38: Yes | S38: 90 | V38: Yes | W38: 90 | Z38: Complete | AA38: Unique | AC38: VA revenue included. | AD38: WO Alias Index + Canonical Ledger
... A48: LED-0047 | B48: 5898644 | C48: 47 | E48: CL-025 | F48: Office of MD Senator Angela Alsobrooks | G48: 46191 | H48: Thursday | I48: Office of MD Senator Angela Alsobrooks | K48: Bowie | L48: Maryland | N48: MD | O48: Bowie|MD | R48: Yes | S48: 130 | V48: Yes | W48: 130 | Z48: Complete | AA48: Unique | AC48: Office of MD Senator Angela Alsobrooks Bowie WO 5898644; breakdown $130 and ACH confirmed July 2. | AD48: WO Alias Index + Canonical Ledger
A49: LED-0048 | B49: 5905576 | C49: 48 | E49: CL-005 | F49: Hebrew Home of Greater Washington | G49: 46191 | H49: Thursday | I49: Hebrew Home of Greater Washington | K49: North Bethesda | L49: Maryland | N49: MD | O49: North Bethesda|MD | R49: Yes | S49: 70 | V49: Mapping Review | Z49: Companion WO mapping review | AA49: Unique | AB49: 5905576 / 5905579 | AC49: Companion WO issue 5905576 / 5905579 remains under ACH mapping review; $35 ACH for 5905579 may relate to companion split or later no-show row. | AD49: WO Alias Index + Canonical Ledger
...

Sheet Analytics
A1: Barrister Analytics Engine — Phase 3F | V1: Client ID | W1: Client | X1: Events | Y1: Work Orders | Z1: Revenue | AA1: Avg/Event | AB1: Avg/WO | AC1: Repeat | AD1: First Event | AE1: Revenue Key | AF1: Repeat Key | AG1: Avg Key | AI1: Service Date | AJ1: Events | AK1: Eligible Events | AL1: Daily Revenue | AM1: Running Revenue | AN1: Rolling 5-Day Avg
V2: =A12 | W2: =B12 | X2: =E12 | Y2: =F12 | Z2: =G12 | AA2: =H12 | AB2: =I12 | AC2: =L12 | AD2: =C12 | AE2: =G12+(1000-C12)/1000000000 | AF2: =E12+G12/1000000000 | AG2: =IF(E12>1,H12+G12/1000000000,0) | AI2: 46132 | AJ2: 1 | AK2: 1 | AL2: 90 | AM2: 90 | AN2: 90
V3: =A13 | W3: =B13 | X3: =E13 | Y3: =F13 | Z3: =G13 | AA3: =H13 | AB3: =I13 | AC3: =L13 | AD3: =C13 | AE3: =G13+(1000-C13)/1000000000 | AF3: =E13+G13/1000000000 | AG3: =IF(E13>1,H13+G13/1000000000,0) | AI3: 46133 | AJ3: 1 | AK3: 1 | AL3: 344 | AM3: 434 | AN3: 217
A4: Analytics Controls | V4: =A14 | W4: =B14 | X4: =E14 | Y4: =F14 | Z4: =G14 | AA4: =H14 | AB4: =I14 | AC4: =L14 | AD4: =C14 | AE4: =G14+(1000-C14)/1000000000 | AF4: =E14+G14/1000000000 | AG4: =IF(E14>1,H14+G14/1000000000,0) | AI4: 46134 | AJ4: 1 | AK4: 1 | AL4: 344 | AM4: 778 | AN4: 259.33
A5: Complete Workweeks | B5: 12 | V5: =A15 | W5: =B15 | X5: =E15 | Y5: =F15 | Z5: =G15 | AA5: =H15 | AB5: =I15 | AC5: =L15 | AD5: =C15 | AE5: =G15+(1000-C15)/1000000000 | AF5: =E15+G15/1000000000 | AG5: =IF(E15>1,H15+G15/1000000000,0) | AI5: 46135 | AJ5: 1 | AK5: 1 | AL5: 180 | AM5: 958 | AN5: 239.5
A6: Completed Events | B6: 72 | V6: =A16 | W6: =B16 | X6: =E16 | Y6: =F16 | Z6: =G16 | AA6: =H16 | AB6: =I16 | AC6: =L16 | AD6: =C16 | AE6: =G16+(1000-C16)/1000000000 | AF6: =E16+G16/1000000000 | AG6: =IF(E16>1,H16+G16/1000000000,0) | AI6: 46136 | AJ6: 1 | AK6: 1 | AL6: 50 | AM6: 1008 | AN6: 201.6
A7: Eligible Confirmed Revenue | B7: 7584.55 | V7: =A17 | W7: =B17 | X7: =E17 | Y7: =F17 | Z7: =G17 | AA7: =H17 | AB7: =I17 | AC7: =L17 | AD7: =C17 | AE7: =G17+(1000-C17)/1000000000 | AF7: =E17+G17/1000000000 | AG7: =IF(E17>1,H17+G17/1000000000,0) | AI7: 46139 | AJ7: 1 | AK7: 1 | AL7: 180 | AM7: 1188 | AN7: 219.6
A8: Eligible Events | B8: =COUNTIFS(tblServiceEvents[Revenue Eligibility],"Eligible") | V8: =A18 | W8: =B18 | X8: =E18 | Y8: =F18 | Z8: =G18 | AA8: =H18 | AB8: =I18 | AC8: =L18 | AD8: =C18 | AE8: =G18+(1000-C18)/1000000000 | AF8: =E18+G18/1000000000 | AG8: =IF(E18>1,H18+G18/1000000000,0) | AI8: 46141 | AJ8: 2 | AK8: 2 | AL8: 95 | AM8: 1283 | AN8: 169.8
A9: Financial-Scope Events | B9: 68 | D9: Chronology-Only Events | E9: 4 | V9: =A19 | W9: =B19 | X9: =E19 | Y9: =F19 | Z9: =G19 | AA9: =H19 | AB9: =I19 | AC9: =L19 | AD9: =C19 | AE9: =G19+(1000-C19)/1000000000 | AF9: =E19+G19/1000000000 | AG9: =IF(E19>1,H19+G19/1000000000,0) | AI9: 46142 | AJ9: 1 | AK9: 0 | AL9: 0 | AM9: 1283 | AN9: 101
A10: Client Summary | V10: =A20 | W10: =B20 | X10: =E20 | Y10: =F20 | Z10: =G20 | AA10: =H20 | AB10: =I20 | AC10: =L20 | AD10: =C20 | AE10: =G20+(1000-C20)/1000000000 | AF10: =E20+G20/1000000000 | AG10: =IF(E20>1,H20+G20/1000000000,0) | AI10: 46147 | AJ10: 1 | AK10: 1 | AL10: 212.5 | AM10: 1495.5 | AN10: 107.5
A11: Client ID | B11: Client Name | C11: First Event | D11: Latest Event | E11: Total Events | F11: Total Work Orders | G11: Confirmed Revenue | H11: Avg Revenue / Event | I11: Avg Revenue / WO | J11: States Worked | K11: Cities Worked | L11: Repeat Client | V11: =A21 | W11: =B21 | X11: =E21 | Y11: =F21 | Z11: =G21 | AA11: =H21 | AB11: =I21 | AC11: =L21 | AD11: =C21 | AE11: =G21+(1000-C21)/1000000000 | AF11: =E21+G21/1000000000 | AG11: =IF(E21>1,H21+G21/1000000000,0) | AI11: 46153 | AJ11: 1 | AK11: 1 | AL11: 157.5 | AM11: 1653 | AN11: 129
A12: CL-001 | B12: Macy's | C12: =MINIFS(tblServiceEvents[Event #],tblServiceEvents[Client],B12) | D12: =MAXIFS(tblServiceEvents[Event #],tblServiceEvents[Client],B12) | E12: =COUNTIFS(tblServiceEvents[Client],B12,tblServiceEvents[Status],"Completed") | F12: =COUNTIF(tblLedger[Client],B12) | G12: =SUMIFS(tblServiceEvents[Confirmed Revenue],tblServiceEvents[Client],B12,tblServiceEvents[Revenue Eligibility],"Eligible") | H12: =IFERROR(G12/COUNTIFS(tblServiceEvents[Client],B12,tblServiceEvents[Revenue Eligibility],"Eligible"),0) | I12: =IFERROR(SUMIFS(tblLedger[Breakdown Amount],tblLedger[Client],B12,tblLedger[Breakdown Confirmed],"Yes")/COUNTIFS(tblLedger[Client],B12,tblLedger[Breakdown Confirmed],"Yes"),0) | J12: 2 | K12: 2 | L12: =IF(E12>1,"Yes","No") | V12: =A22 | W12: =B22 | X12: =E22 | Y12: =F22 | Z12: =G22 | AA12: =H22 | AB12: =I22 | AC12: =L22 | AD12: =C22 | AE12: =G22+(1000-C22)/1000000000 | AF12: =E22+G22/1000000000 | AG12: =IF(E22>1,H22+G22/1000000000,0) | AI12: 46154 | AJ12: 1 | AK12: 1 | AL12: 85 | AM12: 1738 | AN12: 110
A13: CL-002 | B13: Bloomingdale's | C13: =MINIFS(tblServiceEvents[Event #],tblServiceEvents[Client],B13) | D13: =MAXIFS(tblServiceEvents[Event #],tblServiceEvents[Client],B13) | E13: =COUNTIFS(tblServiceEvents[Client],B13,tblServiceEvents[Status],"Completed") | F13: =COUNTIF(tblLedger[Client],B13) | G13: =SUMIFS(tblServiceEvents[Confirmed Revenue],tblServiceEvents[Client],B13,tblServiceEvents[Revenue Eligibility],"Eligible") | H13: =IFERROR(G13/COUNTIFS(tblServiceEvents[Client],B13,tblServiceEvents[Revenue Eligibility],"Eligible"),0) | I13: =IFERROR(SUMIFS(tblLedger[Breakdown Amount],tblLedger[Client],B13,tblLedger[Breakdown Confirmed],"Yes")/COUNTIFS(tblLedger[Client],B13,tblLedger[Breakdown Confirmed],"Yes"),0) | J13: 1 | K13: 1 | L13: =IF(E13>1,"Yes","No") | V13: =A23 | W13: =B23 | X13: =E23 | Y13: =F23 | Z13: =G23 | AA13: =H23 | AB13: =I23 | AC13: =L23 | AD13: =C23 | AE13: =G23+(1000-C23)/1000000000 | AF13: =E23+G23/1000000000 | AG13: =IF(E23>1,H23+G23/1000000000,0) | AI13: 46155 | AJ13: 2 | AK13: 1 | AL13: 50 | AM13: 1788 | AN13: 101
A14: CL-003 | B14: Hampton Inn & Suites | C14: =MINIFS(tblServiceEvents[Event #],tblServiceEvents[Client],B14) | D14: =MAXIFS(tblServiceEvents[Event #],tblServiceEvents[Client],B14) | E14: =COUNTIFS(tblServiceEvents[Client],B14,tblServiceEvents[Status],"Completed") | F14: =COUNTIF(tblLedger[Client],B14) | G14: =SUMIFS(tblServiceEvents[Confirmed Revenue],tblServiceEvents[Client],B14,tblServiceEvents[Revenue Eligibility],"Eligible") | H14: =IFERROR(G14/COUNTIFS(tblServiceEvents[Client],B14,tblServiceEvents[Revenue Eligibility],"Eligible"),0) | I14: =IFERROR(SUMIFS(tblLedger[Breakdown Amount],tblLedger[Client],B14,tblLedger[Breakdown Confirmed],"Yes")/COUNTIFS(tblLedger[Client],B14,tblLedger[Breakdown Confirmed],"Yes"),0) | J14: 2 | K14: 2 | L14: =IF(E14>1,"Yes","No") | V14: =A24 | W14: =B24 | X14: =E24 | Y14: =F24 | Z14: =G24 | AA14: =H24 | AB14: =I24 | AC14: =L24 | AD14: =C24 | AE14: =G24+(1000-C24)/1000000000 | AF14: =E24+G24/1000000000 | AG14: =IF(E24>1,H24+G24/1000000000,0) | AI14: 46156 | AJ14: 1 | AK14: 1 | AL14: 75 | AM14: 1863 | AN14: 116
A15: CL-004 | B15: Davis Polk & Wardwell | C15: =MINIFS(tblServiceEvents[Event #],tblServiceEvents[Client],B15) | D15: =MAXIFS(tblServiceEvents[Event #],tblServiceEvents[Client],B15) | E15: =COUNTIFS(tblServiceEvents[Client],B15,tblServiceEvents[Status],"Completed") | F15: =COUNTIF(tblLedger[Client],B15) | G15: =SUMIFS(tblServiceEvents[Confirmed Revenue],tblServiceEvents[Client],B15,tblServiceEvents[Revenue Eligibility],"Eligible") | H15: =IFERROR(G15/COUNTIFS(tblServiceEvents[Client],B15,tblServiceEvents[Revenue Eligibility],"Eligible"),0) | I15: =IFERROR(SUMIFS(tblLedger[Breakdown Amount],tblLedger[Client],B15,tblLedger[Breakdown Confirmed],"Yes")/COUNTIFS(tblLedger[Client],B15,tblLedger[Breakdown Confirmed],"Yes"),0) | J15: 1 | K15: 1 | L15: =IF(E15>1,"Yes","No") | V15: =A25 | W15: =B25 | X15: =E25 | Y15: =F25 | Z15: =G25 | AA15: =H25 | AB15: =I25 | AC15: =L25 | AD15: =C25 | AE15: =G25+(1000-C25)/1000000000 | AF15: =E25+G25/1000000000 | AG15: =IF(E25>1,H25+G25/1000000000,0) | AI15: 46157 | AJ15: 1 | AK15: 1 | AL15: 45 | AM15: 1908 | AN15: 82.5
A16: CL-005 | B16: Hebrew Home of Greater Washington | C16: =MINIFS(tblServiceEvents[Event #],tblServiceEvents[Client],B16) | D16: =MAXIFS(tblServiceEvents[Event #],tblServiceEvents[Client],B16) | E16: =COUNTIFS(tblServiceEvents[Client],B16,tblServiceEvents[Status],"Completed") | F16: =COUNTIF(tblLedger[Client],B16) | G16: =SUMIFS(tblServiceEvents[Confirmed Revenue],tblServiceEvents[Client],B16,tblServiceEvents[Revenue Eligibility],"Eligible") | H16: =IFERROR(G16/COUNTIFS(tblServiceEvents[Client],B16,tblServiceEvents[Revenue Eligibility],"Eligible"),0) | I16: =IFERROR(SUMIFS(tblLedger[Breakdown Amount],tblLedger[Client],B16,tblLedger[Breakdown Confirmed],"Yes")/COUNTIFS(tblLedger[Client],B16,tblLedger[Breakdown Confirmed],"Yes"),0) | J16: 1 | K16: 1 | L16: =IF(E16>1,"Yes","No") | V16: =A26 | W16: =B26 | X16: =E26 | Y16: =F26 | Z16: =G26 | AA16: =H26 | AB16: =I26 | AC16: =L26 | AD16: =C26 | AE16: =G26+(1000-C26)/1000000000 | AF16: =E26+G26/1000000000 | AG16: =IF(E26>1,H26+G26/1000000000,0) | AI16: 46161 | AJ16: 1 | AK16: 1 | AL16: 50 | AM16: 1958 | AN16: 61
A17: CL-006 | B17: 7-Eleven | C17: =MINIFS(tblServiceEvents[Event #],tblServiceEvents[Client],B17) | D17: =MAXIFS(tblServiceEvents[Event #],tblServiceEvents[Client],B17) | E17: =COUNTIFS(tblServiceEvents[Client],B17,tblServiceEvents[Status],"Completed") | F17: =COUNTIF(tblLedger[Client],B17) | G17: =SUMIFS(tblServiceEvents[Confirmed Revenue],tblServiceEvents[Client],B17,tblServiceEvents[Revenue Eligibility],"Eligible") | H17: =IFERROR(G17/COUNTIFS(tblServiceEvents[Client],B17,tblServiceEvents[Revenue Eligibility],"Eligible"),0) | I17: =IFERROR(SUMIFS(tblLedger[Breakdown Amount],tblLedger[Client],B17,tblLedger[Breakdown Confirmed],"Yes")/COUNTIFS(tblLedger[Client],B17,tblLedger[Breakdown Confirmed],"Yes"),0) | J17: 1 | K17: 3 | L17: =IF(E17>1,"Yes","No") | V17: =A27 | W17: =B27 | X17: =E27 | Y17: =F27 | Z17: =G27 | AA17: =H27 | AB17: =I27 | AC17: =L27 | AD17: =C27 | AE17: =G27+(1000-C27)/1000000000 | AF17: =E27+G27/1000000000 | AG17: =IF(E27>1,H27+G27/1000000000,0) | AI17: 46162 | AJ17: 1 | AK17: 1 | AL17: 106.67 | AM17: 2064.67 | AN17: 65.33
A18: CL-007 | B18: Giant Food Stores | C18: =MINIFS(tblServiceEvents[Event #],tblServiceEvents[Client],B18) | D18: =MAXIFS(tblServiceEvents[Event #],tblServiceEvents[Client],B18) | E18: =COUNTIFS(tblServiceEvents[Client],B18,tblServiceEvents[Status],"Completed") | F18: =COUNTIF(tblLedger[Client],B18) | G18: =SUMIFS(tblServiceEvents[Confirmed Revenue],tblServiceEvents[Client],B18,tblServiceEvents[Revenue Eligibility],"Eligible") | H18: =IFERROR(G18/COUNTIFS(tblServiceEvents[Client],B18,tblServiceEvents[Revenue Eligibility],"Eligible"),0) | I18: =IFERROR(SUMIFS(tblLedger[Breakdown Amount],tblLedger[Client],B18,tblLedger[Breakdown Confirmed],"Yes")/COUNTIFS(tblLedger[Client],B18,tblLedger[Breakdown Confirmed],"Yes"),0) | J18: 2 | K18: 3 | L18: =IF(E18>1,"Yes","No") | V18: =A28 | W18: =B28 | X18: =E28 | Y18: =F28 | Z18: =G28 | AA18: =H28 | AB18: =I28 | AC18: =L28 | AD18: =C28 | AE18: =G28+(1000-C28)/1000000000 | AF18: =E28+G28/1000000000 | AG18: =IF(E28>1,H28+G28/1000000000,0) | AI18: 46163 | AJ18: 2 | AK18: 2 | AL18: 265.83 | AM18: 2330.5 | AN18: 108.5
A19: CL-008 | B19: Food Lion | C19: =MINIFS(tblServiceEvents[Event #],tblServiceEvents[Client],B19) | D19: =MAXIFS(tblServiceEvents[Event #],tblServiceEvents[Client],B19) | E19: =COUNTIFS(tblServiceEvents[Client],B19,tblServiceEvents[Status],"Completed") | F19: =COUNTIF(tblLedger[Client],B19) | G19: =SUMIFS(tblServiceEvents[Confirmed Revenue],tblServiceEvents[Client],B19,tblServiceEvents[Revenue Eligibility],"Eligible") | H19: =IFERROR(G19/COUNTIFS(tblServiceEvents[Client],B19,tblServiceEvents[Revenue Eligibility],"Eligible"),0) | I19: =IFERROR(SUMIFS(tblLedger[Breakdown Amount],tblLedger[Client],B19,tblLedger[Breakdown Confirmed],"Yes")/COUNTIFS(tblLedger[Client],B19,tblLedger[Breakdown Confirmed],"Yes"),0) | J19: 2 | K19: 3 | L19: =IF(E19>1,"Yes","No") | V19: =A29 | W19: =B29 | X19: =E29 | Y19: =F29 | Z19: =G29 | AA19: =H29 | AB19: =I29 | AC19: =L29 | AD19: =C29 | AE19: =G29+(1000-C29)/1000000000 | AF19: =E29+G29/1000000000 | AG19: =IF(E29>1,H29+G29/1000000000,0) | AI19: 46168 | AJ19: 2 | AK19: 2 | AL19: 147.91 | AM19: 2478.41 | AN19: 123.08
A20: CL-009 | B20: Weis Markets | C20: =MINIFS(tblServiceEvents[Event #],tblServiceEvents[Client],B20) | D20: =MAXIFS(tblServiceEvents[Event #],tblServiceEvents[Client],B20) | E20: =COUNTIFS(tblServiceEvents[Client],B20,tblServiceEvents[Status],"Completed") | F20: =COUNTIF(tblLedger[Client],B20) | G20: =SUMIFS(tblServiceEvents[Confirmed Revenue],tblServiceEvents[Client],B20,tblServiceEvents[Revenue Eligibility],"Eligible") | H20: =IFERROR(G20/COUNTIFS(tblServiceEvents[Client],B20,tblServiceEvents[Revenue Eligibility],"Eligible"),0) | I20: =IFERROR(SUMIFS(tblLedger[Breakdown Amount],tblLedger[Client],B20,tblLedger[Breakdown Confirmed],"Yes")/COUNTIFS(tblLedger[Client],B20,tblLedger[Breakdown Confirmed],"Yes"),0) | J20: 2 | K20: 2 | L20: =IF(E20>1,"Yes","No") | V20: =A30 | W20: =B30 | X20: =E30 | Y20: =F30 | Z20: =G30 | AA20: =H30 | AB20: =I30 | AC20: =L30 | AD20: =C30 | AE20: =G30+(1000-C30)/1000000000 | AF20: =E30+G30/1000000000 | AG20: =IF(E30>1,H30+G30/1000000000,0) | AI20: 46169 | AJ20: 2 | AK20: 1 | AL20: 200 | AM20: 2678.41 | AN20: 154.08
A21: CL-010 | B21: Office of MD Senator Chris Van Hollen | C21: =MINIFS(tblServiceEvents[Event #],tblServiceEvents[Client],B21) | D21: =MAXIFS(tblServiceEvents[Event #],tblServiceEvents[Client],B21) | E21: =COUNTIFS(tblServiceEvents[Client],B21,tblServiceEvents[Status],"Completed") | F21: =COUNTIF(tblLedger[Client],B21) | G21: =SUMIFS(tblServiceEvents[Confirmed Revenue],tblServiceEvents[Client],B21,tblServiceEvents[Revenue Eligibility],"Eligible") | H21: =IFERROR(G21/COUNTIFS(tblServiceEvents[Client],B21,tblServiceEvents[Revenue Eligibility],"Eligible"),0) | I21: =IFERROR(SUMIFS(tblLedger[Breakdown Amount],tblLedger[Client],B21,tblLedger[Breakdown Confirmed],"Yes")/COUNTIFS(tblLedger[Client],B21,tblLedger[Breakdown Confirmed],"Yes"),0) | J21: 1 | K21: 1 | L21: =IF(E21>1,"Yes","No") | V21: =A31 | W21: =B31 | X21: =E31 | Y21: =F31 | Z21: =G31 | AA21: =H31 | AB21: =I31 | AC21: =L31 | AD21: =C31 | AE21: =G31+(1000-C31)/1000000000 | AF21: =E31+G31/1000000000 | AG21: =IF(E31>1,H31+G31/1000000000,0) | AI21: 46170 | AJ21: 2 | AK21: 1 | AL21: 175 | AM21: 2853.41 | AN21: 179.08
